frontend/slides/case_studies1.txt
{:format :pointed-dict, :data [{#uuid "ff0051ea-2479-4922-b67e-04ab2bbea9c3" {:updated-at 1726717935090, :entity-type :font, :events [], :type "custom", :keyspace [:workspace #uuid "115577da-7857-4831-9fc4-c520aa2009cb"], :id #uuid "ff0051ea-2479-4922-b67e-04ab2bbea9c3", :styles [{:name "300 Italic", :style "italic", :weight 300, :sources [{:url "https://pitch-assets-ccb95893-de3f-4266-973c-20049231b248.s3.eu-west-1.amazonaws.com/fonts/09adb1f6-a700-4ba7-a69a-fbd373b5f0d3.woff", :format "woff"}]} {:name "300", :style "normal", :weight 300, :sources [{:url "https://pitch-assets-ccb95893-de3f-4266-973c-20049231b248.s3.eu-west-1.amazonaws.com/fonts/e8e7a9a8-4740-4ec6-903a-f76e1547888f.woff", :format "woff"}]} {:name "400 Italic", :style "italic", :weight 400, :sources [{:url "https://pitch-assets-ccb95893-de3f-4266-973c-20049231b248.s3.eu-west-1.amazonaws.com/fonts/71bb8a9f-857a-4094-aba7-67880347413c.woff", :format "woff"}]} {:name "400", :style "normal", :weight 400, :sources [{:url "https://pitch-assets-ccb95893-de3f-4266-973c-20049231b248.s3.eu-west-1.amazonaws.com/fonts/2c948cd8-7a1b-4faa-a5a4-e13eec656717.woff", :format "woff"}]} {:name "500", :style "normal", :weight 500, :sources [{:url "https://pitch-assets-ccb95893-de3f-4266-973c-20049231b248.s3.eu-west-1.amazonaws.com/fonts/c8ef3205-959f-4387-bdd1-b01c7343b583.woff", :format "woff"}]} {:name "550", :style "italic", :weight 500, :sources [{:url "https://pitch-assets-ccb95893-de3f-4266-973c-20049231b248.s3.eu-west-1.amazonaws.com/fonts/e9860aba-c865-4748-8fc0-79cf980868eb.woff", :format "woff"}]} {:name "600", :style "normal", :weight 600, :sources [{:url "https://pitch-assets-ccb95893-de3f-4266-973c-20049231b248.s3.eu-west-1.amazonaws.com/fonts/dae0dbb5-3984-4f40-a3c1-e778f41085e5.woff", :format "woff"}]} {:name "600 (IT)", :style "italic", :weight 600, :sources [{:url "https://pitch-assets-ccb95893-de3f-4266-973c-20049231b248.s3.eu-west-1.amazonaws.com/fonts/b83dc5a6-75de-4850-aad3-a56960d7dad8.woff", :format "woff"}]} {:name "700", :style "normal", :weight 700, :sources [{:url "https://pitch-assets-ccb95893-de3f-4266-973c-20049231b248.s3.eu-west-1.amazonaws.com/fonts/d6e6ff8b-3b98-4a7d-8d2e-bf7e121be581.woff", :format "woff"}]}], :created-at 1726717935090, :font-family "TWK Lausanne"}, #uuid "07c79bbe-fd3f-4fab-8c45-d45d1437cbfa" {:entity-type :block, :text-align :right, :white-space :break-spaces, :font-size 0.45, :font-weight 400, :auto-resize? false, :auto-align-default :left, :coords {:y-start 0.951965238121355, :x-start 0.8773443849967116, :x-end 0.9480619820044631, :y-end 0.9769652381213549}, :events [], :text-color {:r 147, :g 157, :b 168, :a 1}, :auto-vertical-align-default :top, :text-type :paragraph, :used-fonts #{#uuid "ff0051ea-2479-4922-b67e-04ab2bbea9c3"}, :id #uuid "07c79bbe-fd3f-4fab-8c45-d45d1437cbfa", :block-type :text, :body "<p><span style=\"font-weight:400\"><span style=\"text-decoration:none\">Augusta Labs</span></span></p>", :font-family "font-ff0051ea-2479-4922-b67e-04ab2bbea9c3"}, #uuid "d286fd29-b940-4632-a8d7-ea5220797473" {:line-height 0.75, :font-style "italic", :entity-type :block, :text-align :right, :white-space :break-spaces, :font-size 0.9, :font-weight 500, :auto-resize? true, :auto-align-default :left, :coords {:x-start 0.27991768374946313, :y-start 0.8026543105966559, :x-end 0.45596656993057977, :y-end 0.8582098645074691}, :events [], :text-color {:r 147, :g 157, :b 168, :a 1}, :auto-vertical-align-default :top, :text-align-vertical :top, :text-type :headline-medium, :used-fonts #{#uuid "ff00e4cf-60ba-4f16-951a-72c5311ef140"}, :id #uuid "d286fd29-b940-4632-a8d7-ea5220797473", :block-type :text, :body "<p><span style=\"font-size:2.22222em\"><span style=\"letter-spacing:-0.05em\">3x</span></span><span style=\"font-size:0.611111em\"><span style=\"letter-spacing:-0.05em\">   </span><span style=\"font-style:normal\"><span style=\"font-weight:400\">Faster AI Product Rollout</span></span></span></p>"}, #uuid "a0e84e8b-573a-4ce8-b7b2-33dde3b800f6" {:line-height 1, :entity-type :block, :text-align :center, :white-space :break-spaces, :font-size 0.4, :font-weight 500, :auto-resize? false, :auto-align-default :left, :coords {:y-start 0.008481540613149319, :x-start 0.00012376134901242314, :x-end 0.06316629474668697, :y-end 0.023296355427964155}, :events [], :text-color {:r 147, :g 157, :b 168, :a 1}, :auto-vertical-align-default :top, :text-align-vertical :bottom, :text-type :headline-medium, :used-fonts #{#uuid "ff00e4cf-60ba-4f16-951a-72c5311ef140"}, :id #uuid "a0e84e8b-573a-4ce8-b7b2-33dde3b800f6", :block-type :text, :body "<p>SOFTWARE</p>"}, #uuid "ff00e4cf-60ba-4f16-951a-72c5311ef140" {:updated-at 1711211845800, :entity-type :font, :events [], :type "custom", :keyspace [:workspace #uuid "115577da-7857-4831-9fc4-c520aa2009cb"], :id #uuid "ff00e4cf-60ba-4f16-951a-72c5311ef140", :styles [{:name "Regular Thinner", :style "normal", :weight 100, :sources [{:url "https://pitch-assets-ccb95893-de3f-4266-973c-20049231b248.s3.eu-west-1.amazonaws.com/fonts/5015d499-033e-4564-bacb-62957c24e037.woff", :format "woff"}]} {:name "Ultralight Italic", :style "italic", :weight 200, :sources [{:url "https://pitch-assets-ccb95893-de3f-4266-973c-20049231b248.s3.eu-west-1.amazonaws.com/fonts/a7377dcb-7ee1-4530-bb19-5fd6da572d26.woff", :format "woff"}]} {:name "Light Italic", :style "italic", :weight 300, :sources [{:url "https://pitch-assets-ccb95893-de3f-4266-973c-20049231b248.s3.eu-west-1.amazonaws.com/fonts/4085c36a-a11f-4647-a6ff-4667a90f297b.woff", :format "woff"}]} {:name "Light", :style "normal", :weight 300, :sources [{:url "https://pitch-assets-ccb95893-de3f-4266-973c-20049231b248.s3.eu-west-1.amazonaws.com/fonts/f81a9a9b-4e76-471c-99b4-ab038107935b.woff", :format "woff"}]} {:name "Regular Italic", :style "italic", :weight 400, :sources [{:url "https://pitch-assets-ccb95893-de3f-4266-973c-20049231b248.s3.eu-west-1.amazonaws.com/fonts/bb34c7d8-2580-435b-a5d2-09204870cd07.woff", :format "woff"}]} {:name "Regular", :style "normal", :weight 400, :sources [{:url "https://pitch-assets-ccb95893-de3f-4266-973c-20049231b248.s3.eu-west-1.amazonaws.com/fonts/5f5cf5a6-67a8-45bc-8248-886c6314e6fc.woff", :format "woff"}]} {:name "Medium Italic", :style "italic", :weight 500, :sources [{:url "https://pitch-assets-ccb95893-de3f-4266-973c-20049231b248.s3.eu-west-1.amazonaws.com/fonts/80d4291d-5b50-4431-a50f-711e8e991b0d.woff", :format "woff"}]} {:name "Medium", :style "normal", :weight 500, :sources [{:url "https://pitch-assets-ccb95893-de3f-4266-973c-20049231b248.s3.eu-west-1.amazonaws.com/fonts/6fd7b72a-0c16-41bc-a93d-662ebdae3881.woff", :format "woff"}]} {:name "Semibold Italic", :style "italic", :weight 600, :sources [{:url "https://pitch-assets-ccb95893-de3f-4266-973c-20049231b248.s3.eu-west-1.amazonaws.com/fonts/5cfe84b0-7a92-46d9-b4cd-91f3355bd87e.woff", :format "woff"}]} {:name "Semibold", :style "normal", :weight 600, :sources [{:url "https://pitch-assets-ccb95893-de3f-4266-973c-20049231b248.s3.eu-west-1.amazonaws.com/fonts/b798cb33-5e74-46e3-bf2d-6a2778148ae7.woff", :format "woff"}]} {:name "Bold", :style "normal", :weight 700, :sources [{:url "https://pitch-assets-ccb95893-de3f-4266-973c-20049231b248.s3.eu-west-1.amazonaws.com/fonts/b08a3a24-c74c-48d1-a63f-58afe6afc15a.woff", :format "woff"}]} {:name "Bold Italic", :style "italic", :weight 700, :sources [{:url "https://pitch-assets-ccb95893-de3f-4266-973c-20049231b248.s3.eu-west-1.amazonaws.com/fonts/6acab0f1-ac72-49dd-9df4-55ce8f160c49.woff", :format "woff"}]} {:name "Heavy Italic", :style "italic", :weight 850, :sources [{:url "https://pitch-assets-ccb95893-de3f-4266-973c-20049231b248.s3.eu-west-1.amazonaws.com/fonts/9dc7546d-cf9e-4ce2-94f8-4a5e349db57c.woff", :format "woff"}]} {:name "Heavy", :style "normal", :weight 850, :sources [{:url "https://pitch-assets-ccb95893-de3f-4266-973c-20049231b248.s3.eu-west-1.amazonaws.com/fonts/811b80e7-de6e-4e7a-a5a5-b228719ec927.woff", :format "woff"}]} {:name "Black Italic", :style "italic"
