frontend/slides/case_studies2.txt
{:format :pointed-dict, :data [{#uuid "ff0051ea-2479-4922-b67e-04ab2bbea9c3" {:updated-at 1726717935090, :entity-type :font, :events [], :type "custom", :keyspace [:workspace #uuid "115577da-7857-4831-9fc4-c520aa2009cb"], :id #uuid "ff0051ea-2479-4922-b67e-04ab2bbea9c3", :styles [{:name "300 Italic", :style "italic", :weight 300, :sources [{:url "https://pitch-assets-ccb95893-de3f-4266-973c-20049231b248.s3.eu-west-1.amazonaws.com/fonts/09adb1f6-a700-4ba7-a69a-fbd373b5f0d3.woff", :format "woff"}]} {:name "300", :style "normal", :weight 300, :sources [{:url "https://pitch-assets-ccb95893-de3f-4266-973c-20049231b248.s3.eu-west-1.amazonaws.com/fonts/e8e7a9a8-4740-4ec6-903a-f76e1547888f.woff", :format "woff"}]} {:name "400 Italic", :style "italic", :weight 400, :sources [{:url "https://pitch-assets-ccb95893-de3f-4266-973c-20049231b248.s3.eu-west-1.amazonaws.com/fonts/71bb8a9f-857a-4094-aba7-67880347413c.woff", :format "woff"}]} {:name "400", :style "normal", :weight 400, :sources [{:url "https://pitch-assets-ccb95893-de3f-4266-973c-20049231b248.s3.eu-west-1.amazonaws.com/fonts/2c948cd8-7a1b-4faa-a5a4-e13eec656717.woff", :format "woff"}]} {:name "500", :style "normal", :weight 500, :sources [{:url "https://pitch-assets-ccb95893-de3f-4266-973c-20049231b248.s3.eu-west-1.amazonaws.com/fonts/c8ef3205-959f-4387-bdd1-b01c7343b583.woff", :format "woff"}]} {:name "550", :style "italic", :weight 500, :sources [{:url "https://pitch-assets-ccb95893-de3f-4266-973c-20049231b248.s3.eu-west-1.amazonaws.com/fonts/e9860aba-c865-4748-8fc0-79cf980868eb.woff", :format "woff"}]} {:name "600", :style "normal", :weight 600, :sources [{:url "https://pitch-assets-ccb95893-de3f-4266-973c-20049231b248.s3.eu-west-1.amazonaws.com/fonts/dae0dbb5-3984-4f40-a3c1-e778f41085e5.woff", :format "woff"}]} {:name "600 (IT)", :style "italic", :weight 600, :sources [{:url "https://pitch-assets-ccb95893-de3f-4266-973c-20049231b248.s3.eu-west-1.amazonaws.com/fonts/b83dc5a6-75de-4850-aad3-a56960d7dad8.woff", :format "woff"}]} {:name "700", :style "normal", :weight 700, :sources [{:url "https://pitch-assets-ccb95893-de3f-4266-973c-20049231b248.s3.eu-west-1.amazonaws.com/fonts/d6e6ff8b-3b98-4a7d-8d2e-bf7e121be581.woff", :format "woff"}]}], :created-at 1726717935090, :font-family "TWK Lausanne"}, #uuid "784dcd89-11aa-49ee-90b9-e64ad1713efa" {:fill-color {:r 147, :g 157, :b 168, :a 1}, :entity-type :block, :shape-type :rectangle, :white-space :break-spaces, :coords {:y-start 0.6458598528465659, :x-start 0.5164239151844161, :x-end 0.9699047427153549, :y-end 0.6467857787724918}, :events [], :border? true, :even-padding? true, :border-width 0, :opacity 0.7, :id #uuid "784dcd89-11aa-49ee-90b9-e64ad1713efa", :block-type :shape, :border-color {:r 229, :g 231, :b 240, :a 1}, :body "<p></p>", :arrowhead-type :triangle}, #uuid "a9019f81-7069-4a93-84a3-0e4e2a6157d4" {:fill-color {:r 147, :g 157, :b 168, :a 1}, :entity-type :block, :shape-type :rectangle, :white-space :break-spaces, :coords {:y-start 0.8121478077724329, :x-start 0.5161400152675681, :x-end 0.9696208427985069, :y-end 0.8130737336983588}, :events [], :border? true, :even-padding? true, :border-width 0, :opacity 0.7, :id #uuid "a9019f81-7069-4a93-84a3-0e4e2a6157d4", :block-type :shape, :border-color {:r 229, :g 231, :b 240, :a 1}, :body "<p></p>", :arrowhead-type :triangle}, #uuid "3b044704-56ae-4c61-925b-c6b58f3ba4c3" {:entity-type :block, :text-align :right, :white-space :break-spaces, :font-size 0.45, :font-weight 400, :auto-resize? false, :auto-align-default :left, :coords {:y-start 0.951965238121355, :x-start 0.8773443849967116, :x-end 0.9480619820044631, :y-end 0.9769652381213549}, :events [], :text-color {:r 147, :g 157, :b 168, :a 1}, :auto-vertical-align-default :top, :text-type :paragraph, :used-fonts #{#uuid "ff0051ea-2479-4922-b67e-04ab2bbea9c3"}, :id #uuid "3b044704-56ae-4c61-925b-c6b58f3ba4c3", :block-type :text, :body "<p><span style=\"font-weight:400\"><span style=\"text-decoration:none\">Augusta Labs</span></span></p>", :font-family "font-ff0051ea-2479-4922-b67e-04ab2bbea9c3"}, #uuid "69fd8a28-aff1-4bfe-9880-0a8c468b98af" {:line-height 1.25, :entity-type :block, :text-align :left, :white-space :break-spaces, :font-size 0.5, :font-weight 400, :auto-resize? true, :auto-align-default :left, :coords {:x-start 0.10305371332128228, :y-start 0.5476422773418229, :x-end 0.4841373045370633, :y-end 0.6170867234310098}, :events [], :text-color {:r 147, :g 157, :b 168, :a 1}, :auto-vertical-align-default :top, :text-align-vertical :top, :text-type :headline-medium, :opacity 0.6, :id #uuid "69fd8a28-aff1-4bfe-9880-0a8c468b98af", :block-type :text, :letter-spacing -0.02, :body "<ul><li><p><span style=\"font-weight:400\">Teams manually review hundreds of pages per tender under intense bid deadlines.</span></p></li><li><p><span style=\"font-weight:400\">Minor clause gaps or missing documents often lead to costly disqualifications.</span></p></li><li><p><span style=\"font-weight:400\">Historic pricing and supplier data remain locked in silos, limiting insights.</span></p></li></ul>"}, #uuid "3d9bf56a-6c40-4416-a1fa-2bb4da2db96e" {:fill-color {:r 147, :g 157, :b 168, :a 1}, :entity-type :block, :coords {:x-start 0.02121715341542371, :x-end 0.03580048674875704, :y-start 0.038915739905289355, :y-end 0.06484166583121528}, :events [], :original-aspect-ratio? true, :image-aspect-ratio 1, :id #uuid "3d9bf56a-6c40-4416-a1fa-2bb4da2db96e", :image-position {:x 50, :y 50}, :url "https://icon-sets.static.services.pitch.com/icon-sets/Material-Outlined/map.svg", :block-type :image, :image-scale-x 1, :locked-aspect-ratio? true, :created-at 1761119963438}, #uuid "7d72f2e5-d4e1-4e34-b014-8e163521103a" {:line-height 1.25, :font-style "italic", :entity-type :block, :text-transform "uppercase", :text-align :left, :white-space :break-spaces, :font-size 0.4, :font-weight 500, :auto-resize? true, :auto-align-default :left, :coords {:y-start 0.6719797246697232, :x-start 0.029796044537267044, :x-end 0.07074656537060037, :y-end 0.6904982431882417}, :events [], :text-color {:r 84, :g 84, :b 101, :a 1}, :auto-vertical-align-default :top, :text-align-vertical :top, :text-type :headline-medium, :opacity 1, :id #uuid "7d72f2e5-d4e1-4e34-b014-8e163521103a", :block-type :text, :letter-spacing -0.02, :body "<p>Solution</p>"}, #uuid "86df7cad-5ef9-4667-abf4-d134742e6ad6" {:line-height 1.25, :font-style "italic", :entity-type :block, :text-transform "uppercase", :text-align :left, :white-space :break-spaces, :font-size 0.4, :font-weight 500, :auto-resize? true, :auto-align-default :left, :coords {:y-start 0.6714750137064378, :x-start 0.5161105205028031, :x-end 0.5570610413361364, :y-end 0.6899935322249563}, :events [], :text-color {:r 84, :g 84, :b 101, :a 1}, :auto-vertical-align-default :top, :text-align-vertical :top, :text-type :headline-medium, :opacity 1, :id #uuid "86df7cad-5ef9-4667-abf4-d134742e6ad6", :block-type :text, :letter-spacing -0.02, :body "<p>Solution</p>"}, #uuid "40e874ab-52e8-48c8-9d99-e4be13c3330c" {:fill-color {:r 255, :g 255, :b 255, :a 1}, :entity-type :block, :coords {:x-start 0.039736131194583836, :x-end 0.10175903195794224, :y-start 0.28046565741213647, :y-end 0.30453973148621055}, :events [], :original-aspect-ratio? true, :used-fonts #{#uuid "ff00e4cf-60ba-4f16-951a-72c5311ef140"}, :image-aspect-ratio 4.580152671755725, :id #uuid "40e874ab-52e8-48c8-9d99-e4be13c3330c", :url "https://asset.brandfetch.io/idHoK8WPgP/idPhXXtfol.svg", :block-type :image, :image-scale-x 1, :locked-aspect-ratio? true, :created-at 1747070032896}, #uuid "460e10d0-ed54-428e-b43f-b76ae07f4a6d" {:fill-color {:r 229, :g 231, :b 240, :a 1}, :entity-type :block, :shape-type :rectangle, :white-space :break-spaces, :coords {:x-start 0.021010018407882636, :x-end 0.9784172059078828, :y-start 0.9416943107132394, :y-end 0.9435461625650912}, :events [], :border? true, :even-padding? true, :border-width 0, :id #uuid "460e10d0-ed54-428e-b43f-b76ae07f4a6d", :block-type :shape, :border-color {:r 22
